INFO:     Uvicorn running on http://0.0.0.0:8000 (Press CTRL+C to quit)
INFO:     Started reloader process [2462] using statreload
INFO:     Started server process [2464]
INFO:     Waiting for application startup.
INFO:     Application startup complete.
INFO:     192.168.0.1:64841 - "GET / HTTP/1.1" 200 OK
INFO:     192.168.0.1:64841 - "GET /favicon.ico HTTP/1.1" 404 Not Found
INFO:     192.168.0.1:64841 - "GET /docs HTTP/1.1" 200 OK
INFO:     192.168.0.1:64841 - "GET /openapi.json HTTP/1.1" 200 OK
INFO:     167.248.133.37:41474 - "GET / HTTP/1.1" 200 OK
INFO:     167.248.133.37:41850 - "GET / HTTP/1.1" 200 OK
INFO:     34.86.35.19:33633 - "GET / HTTP/1.1" 200 OK
INFO:     112.217.167.202:1509 - "GET /docs HTTP/1.1" 200 OK
INFO:     112.217.167.202:1509 - "GET /openapi.json HTTP/1.1" 200 OK
WARNING:  Invalid HTTP request received.
Traceback (most recent call last):
  File "/home/wooseok/anaconda3/envs/LGAPI/lib/python3.7/site-packages/uvicorn/protocols/http/h11_impl.py", line 172, in handle_events
    event = self.conn.next_event()
  File "/home/wooseok/anaconda3/envs/LGAPI/lib/python3.7/site-packages/h11/_connection.py", line 443, in next_event
    exc._reraise_as_remote_protocol_error()
  File "/home/wooseok/anaconda3/envs/LGAPI/lib/python3.7/site-packages/h11/_util.py", line 76, in _reraise_as_remote_protocol_error
    raise self
  File "/home/wooseok/anaconda3/envs/LGAPI/lib/python3.7/site-packages/h11/_connection.py", line 425, in next_event
    event = self._extract_next_receive_event()
  File "/home/wooseok/anaconda3/envs/LGAPI/lib/python3.7/site-packages/h11/_connection.py", line 367, in _extract_next_receive_event
    event = self._reader(self._receive_buffer)
  File "/home/wooseok/anaconda3/envs/LGAPI/lib/python3.7/site-packages/h11/_readers.py", line 68, in maybe_read_from_IDLE_client
    raise LocalProtocolError("illegal request line")
h11._util.RemoteProtocolError: illegal request line
INFO:     175.223.15.58:14229 - "GET /docs HTTP/1.1" 200 OK
INFO:     175.223.15.58:14229 - "GET /openapi.json HTTP/1.1" 200 OK
INFO:     112.217.167.202:20357 - "GET /docs HTTP/1.1" 200 OK
INFO:     112.217.167.202:20357 - "GET /openapi.json HTTP/1.1" 200 OK
INFO:     112.217.167.202:21149 - "GET /docs HTTP/1.1" 200 OK
INFO:     112.217.167.202:21149 - "GET /openapi.json HTTP/1.1" 200 OK
INFO:     58.227.149.49:59753 - "GET /openapi.json HTTP/1.1" 200 OK
INFO:     185.216.140.186:35874 - "GET http%3A//www.baidu.com/cache/global/img/gs.gif HTTP/1.1" 404 Not Found
INFO:     216.218.206.69:53570 - "GET / HTTP/1.1" 200 OK
WARNING:  Invalid HTTP request received.
Traceback (most recent call last):
  File "/home/wooseok/anaconda3/envs/LGAPI/lib/python3.7/site-packages/uvicorn/protocols/http/h11_impl.py", line 172, in handle_events
    event = self.conn.next_event()
  File "/home/wooseok/anaconda3/envs/LGAPI/lib/python3.7/site-packages/h11/_connection.py", line 443, in next_event
    exc._reraise_as_remote_protocol_error()
  File "/home/wooseok/anaconda3/envs/LGAPI/lib/python3.7/site-packages/h11/_util.py", line 76, in _reraise_as_remote_protocol_error
    raise self
  File "/home/wooseok/anaconda3/envs/LGAPI/lib/python3.7/site-packages/h11/_connection.py", line 425, in next_event
    event = self._extract_next_receive_event()
  File "/home/wooseok/anaconda3/envs/LGAPI/lib/python3.7/site-packages/h11/_connection.py", line 367, in _extract_next_receive_event
    event = self._reader(self._receive_buffer)
  File "/home/wooseok/anaconda3/envs/LGAPI/lib/python3.7/site-packages/h11/_readers.py", line 68, in maybe_read_from_IDLE_client
    raise LocalProtocolError("illegal request line")
h11._util.RemoteProtocolError: illegal request line
WARNING:  Invalid HTTP request received.
Traceback (most recent call last):
  File "/home/wooseok/anaconda3/envs/LGAPI/lib/python3.7/site-packages/uvicorn/protocols/http/h11_impl.py", line 172, in handle_events
    event = self.conn.next_event()
  File "/home/wooseok/anaconda3/envs/LGAPI/lib/python3.7/site-packages/h11/_connection.py", line 443, in next_event
    exc._reraise_as_remote_protocol_error()
  File "/home/wooseok/anaconda3/envs/LGAPI/lib/python3.7/site-packages/h11/_util.py", line 76, in _reraise_as_remote_protocol_error
    raise self
  File "/home/wooseok/anaconda3/envs/LGAPI/lib/python3.7/site-packages/h11/_connection.py", line 425, in next_event
    event = self._extract_next_receive_event()
  File "/home/wooseok/anaconda3/envs/LGAPI/lib/python3.7/site-packages/h11/_connection.py", line 367, in _extract_next_receive_event
    event = self._reader(self._receive_buffer)
  File "/home/wooseok/anaconda3/envs/LGAPI/lib/python3.7/site-packages/h11/_readers.py", line 68, in maybe_read_from_IDLE_client
    raise LocalProtocolError("illegal request line")
h11._util.RemoteProtocolError: illegal request line
WARNING:  Invalid HTTP request received.
Traceback (most recent call last):
  File "/home/wooseok/anaconda3/envs/LGAPI/lib/python3.7/site-packages/uvicorn/protocols/http/h11_impl.py", line 172, in handle_events
    event = self.conn.next_event()
  File "/home/wooseok/anaconda3/envs/LGAPI/lib/python3.7/site-packages/h11/_connection.py", line 443, in next_event
    exc._reraise_as_remote_protocol_error()
  File "/home/wooseok/anaconda3/envs/LGAPI/lib/python3.7/site-packages/h11/_util.py", line 76, in _reraise_as_remote_protocol_error
    raise self
  File "/home/wooseok/anaconda3/envs/LGAPI/lib/python3.7/site-packages/h11/_connection.py", line 425, in next_event
    event = self._extract_next_receive_event()
  File "/home/wooseok/anaconda3/envs/LGAPI/lib/python3.7/site-packages/h11/_connection.py", line 367, in _extract_next_receive_event
    event = self._reader(self._receive_buffer)
  File "/home/wooseok/anaconda3/envs/LGAPI/lib/python3.7/site-packages/h11/_readers.py", line 68, in maybe_read_from_IDLE_client
    raise LocalProtocolError("illegal request line")
h11._util.RemoteProtocolError: illegal request line
INFO:     185.216.140.186:46024 - "GET http%3A//www.baidu.com/cache/global/img/gs.gif HTTP/1.1" 404 Not Found
INFO:     160.251.6.176:54520 - "POST /_ignition/execute-solution HTTP/1.1" 404 Not Found
INFO:     167.99.218.251:39344 - "GET / HTTP/1.1" 200 OK
WARNING:  Invalid HTTP request received.
Traceback (most recent call last):
  File "/home/wooseok/anaconda3/envs/LGAPI/lib/python3.7/site-packages/uvicorn/protocols/http/h11_impl.py", line 172, in handle_events
    event = self.conn.next_event()
  File "/home/wooseok/anaconda3/envs/LGAPI/lib/python3.7/site-packages/h11/_connection.py", line 443, in next_event
    exc._reraise_as_remote_protocol_error()
  File "/home/wooseok/anaconda3/envs/LGAPI/lib/python3.7/site-packages/h11/_util.py", line 76, in _reraise_as_remote_protocol_error
    raise self
  File "/home/wooseok/anaconda3/envs/LGAPI/lib/python3.7/site-packages/h11/_connection.py", line 425, in next_event
    event = self._extract_next_receive_event()
  File "/home/wooseok/anaconda3/envs/LGAPI/lib/python3.7/site-packages/h11/_connection.py", line 367, in _extract_next_receive_event
    event = self._reader(self._receive_buffer)
  File "/home/wooseok/anaconda3/envs/LGAPI/lib/python3.7/site-packages/h11/_readers.py", line 68, in maybe_read_from_IDLE_client
    raise LocalProtocolError("illegal request line")
h11._util.RemoteProtocolError: illegal request line
INFO:     162.142.125.40:51018 - "GET / HTTP/1.1" 200 OK
INFO:     162.142.125.40:56974 - "GET / HTTP/1.1" 200 OK
INFO:     74.82.47.3:48578 - "GET / HTTP/1.1" 200 OK
INFO:     128.14.209.250:59056 - "GET / HTTP/1.1" 200 OK
INFO:     185.165.190.17:36338 - "GET / HTTP/1.1" 200 OK
INFO:     185.165.190.17:41582 - "GET /favicon.ico HTTP/1.1" 404 Not Found
WARNING:  Invalid HTTP request received.
Traceback (most recent call last):
  File "/home/wooseok/anaconda3/envs/LGAPI/lib/python3.7/site-packages/uvicorn/protocols/http/h11_impl.py", line 172, in handle_events
    event = self.conn.next_event()
  File "/home/wooseok/anaconda3/envs/LGAPI/lib/python3.7/site-packages/h11/_connection.py", line 443, in next_event
    exc._reraise_as_remote_protocol_error()
  File "/home/wooseok/anaconda3/envs/LGAPI/lib/python3.7/site-packages/h11/_util.py", line 76, in _reraise_as_remote_protocol_error
    raise self
  File "/home/wooseok/anaconda3/envs/LGAPI/lib/python3.7/site-packages/h11/_connection.py", line 425, in next_event
    event = self._extract_next_receive_event()
  File "/home/wooseok/anaconda3/envs/LGAPI/lib/python3.7/site-packages/h11/_connection.py", line 367, in _extract_next_receive_event
    event = self._reader(self._receive_buffer)
  File "/home/wooseok/anaconda3/envs/LGAPI/lib/python3.7/site-packages/h11/_readers.py", line 68, in maybe_read_from_IDLE_client
    raise LocalProtocolError("illegal request line")
h11._util.RemoteProtocolError: illegal request line
INFO:     34.76.80.167:37462 - "GET / HTTP/1.1" 200 OK
INFO:     183.136.225.14:14570 - "GET / HTTP/1.1" 200 OK
INFO:     183.136.225.14:11277 - "GET / HTTP/1.1" 200 OK
INFO:     183.136.225.14:12535 - "GET /favicon.ico HTTP/1.1" 404 Not Found
INFO:     188.166.240.102:51974 - "HEAD / HTTP/1.0" 405 Method Not Allowed
INFO:     188.166.240.102:52004 - "GET /system_api.php HTTP/1.1" 404 Not Found
INFO:     188.166.240.102:52220 - "GET /system_api.php HTTP/1.1" 404 Not Found
INFO:     188.166.240.102:52428 - "GET /c/version.js HTTP/1.1" 404 Not Found
INFO:     188.166.240.102:52614 - "GET /streaming/clients_live.php HTTP/1.1" 404 Not Found
INFO:     188.166.240.102:52794 - "GET /stalker_portal/c/version.js HTTP/1.1" 404 Not Found
INFO:     188.166.240.102:52968 - "GET /client_area/ HTTP/1.1" 404 Not Found
INFO:     188.166.240.102:53148 - "GET /stalker_portal/c/ HTTP/1.1" 404 Not Found
INFO:     188.166.240.102:53374 - "GET /stream/live.php HTTP/1.1" 404 Not Found
WARNING:  Invalid HTTP request received.
Traceback (most recent call last):
  File "/home/wooseok/anaconda3/envs/LGAPI/lib/python3.7/site-packages/uvicorn/protocols/http/h11_impl.py", line 172, in handle_events
    event = self.conn.next_event()
  File "/home/wooseok/anaconda3/envs/LGAPI/lib/python3.7/site-packages/h11/_connection.py", line 443, in next_event
    exc._reraise_as_remote_protocol_error()
  File "/home/wooseok/anaconda3/envs/LGAPI/lib/python3.7/site-packages/h11/_util.py", line 76, in _reraise_as_remote_protocol_error
    raise self
  File "/home/wooseok/anaconda3/envs/LGAPI/lib/python3.7/site-packages/h11/_connection.py", line 425, in next_event
    event = self._extract_next_receive_event()
  File "/home/wooseok/anaconda3/envs/LGAPI/lib/python3.7/site-packages/h11/_connection.py", line 367, in _extract_next_receive_event
    event = self._reader(self._receive_buffer)
  File "/home/wooseok/anaconda3/envs/LGAPI/lib/python3.7/site-packages/h11/_readers.py", line 68, in maybe_read_from_IDLE_client
    raise LocalProtocolError("illegal request line")
h11._util.RemoteProtocolError: illegal request line
INFO:     104.206.128.78:42919 - "GET / HTTP/1.1" 200 OK
WARNING:  Invalid HTTP request received.
Traceback (most recent call last):
  File "/home/wooseok/anaconda3/envs/LGAPI/lib/python3.7/site-packages/uvicorn/protocols/http/h11_impl.py", line 172, in handle_events
    event = self.conn.next_event()
  File "/home/wooseok/anaconda3/envs/LGAPI/lib/python3.7/site-packages/h11/_connection.py", line 443, in next_event
    exc._reraise_as_remote_protocol_error()
  File "/home/wooseok/anaconda3/envs/LGAPI/lib/python3.7/site-packages/h11/_util.py", line 76, in _reraise_as_remote_protocol_error
    raise self
  File "/home/wooseok/anaconda3/envs/LGAPI/lib/python3.7/site-packages/h11/_connection.py", line 425, in next_event
    event = self._extract_next_receive_event()
  File "/home/wooseok/anaconda3/envs/LGAPI/lib/python3.7/site-packages/h11/_connection.py", line 367, in _extract_next_receive_event
    event = self._reader(self._receive_buffer)
  File "/home/wooseok/anaconda3/envs/LGAPI/lib/python3.7/site-packages/h11/_readers.py", line 68, in maybe_read_from_IDLE_client
    raise LocalProtocolError("illegal request line")
h11._util.RemoteProtocolError: illegal request line
WARNING:  Invalid HTTP request received.
Traceback (most recent call last):
  File "/home/wooseok/anaconda3/envs/LGAPI/lib/python3.7/site-packages/uvicorn/protocols/http/h11_impl.py", line 172, in handle_events
    event = self.conn.next_event()
  File "/home/wooseok/anaconda3/envs/LGAPI/lib/python3.7/site-packages/h11/_connection.py", line 443, in next_event
    exc._reraise_as_remote_protocol_error()
  File "/home/wooseok/anaconda3/envs/LGAPI/lib/python3.7/site-packages/h11/_util.py", line 76, in _reraise_as_remote_protocol_error
    raise self
  File "/home/wooseok/anaconda3/envs/LGAPI/lib/python3.7/site-packages/h11/_connection.py", line 425, in next_event
    event = self._extract_next_receive_event()
  File "/home/wooseok/anaconda3/envs/LGAPI/lib/python3.7/site-packages/h11/_connection.py", line 367, in _extract_next_receive_event
    event = self._reader(self._receive_buffer)
  File "/home/wooseok/anaconda3/envs/LGAPI/lib/python3.7/site-packages/h11/_readers.py", line 68, in maybe_read_from_IDLE_client
    raise LocalProtocolError("illegal request line")
h11._util.RemoteProtocolError: illegal request line
INFO:     184.105.139.68:47176 - "GET / HTTP/1.1" 200 OK
INFO:     121.4.55.249:38318 - "POST /_ignition/execute-solution HTTP/1.1" 404 Not Found
INFO:     209.141.46.116:36384 - "GET /console/login/LoginForm.jsp HTTP/1.1" 404 Not Found
INFO:     121.41.105.22:41172 - "POST /_ignition/execute-solution HTTP/1.1" 404 Not Found
INFO:     167.248.133.54:35242 - "GET / HTTP/1.1" 200 OK
INFO:     167.248.133.54:37496 - "GET / HTTP/1.1" 200 OK
INFO:     89.248.164.165:58542 - "GET http%3A//www.baidu.com/cache/global/img/gs.gif HTTP/1.1" 404 Not Found
INFO:     23.129.64.204:16423 - "GET / HTTP/1.1" 200 OK
WARNING:  Invalid HTTP request received.
Traceback (most recent call last):
  File "/home/wooseok/anaconda3/envs/LGAPI/lib/python3.7/site-packages/uvicorn/protocols/http/h11_impl.py", line 172, in handle_events
    event = self.conn.next_event()
  File "/home/wooseok/anaconda3/envs/LGAPI/lib/python3.7/site-packages/h11/_connection.py", line 443, in next_event
    exc._reraise_as_remote_protocol_error()
  File "/home/wooseok/anaconda3/envs/LGAPI/lib/python3.7/site-packages/h11/_util.py", line 76, in _reraise_as_remote_protocol_error
    raise self
  File "/home/wooseok/anaconda3/envs/LGAPI/lib/python3.7/site-packages/h11/_connection.py", line 425, in next_event
    event = self._extract_next_receive_event()
  File "/home/wooseok/anaconda3/envs/LGAPI/lib/python3.7/site-packages/h11/_connection.py", line 367, in _extract_next_receive_event
    event = self._reader(self._receive_buffer)
  File "/home/wooseok/anaconda3/envs/LGAPI/lib/python3.7/site-packages/h11/_readers.py", line 68, in maybe_read_from_IDLE_client
    raise LocalProtocolError("illegal request line")
h11._util.RemoteProtocolError: illegal request line
WARNING:  Invalid HTTP request received.
Traceback (most recent call last):
  File "/home/wooseok/anaconda3/envs/LGAPI/lib/python3.7/site-packages/uvicorn/protocols/http/h11_impl.py", line 172, in handle_events
    event = self.conn.next_event()
  File "/home/wooseok/anaconda3/envs/LGAPI/lib/python3.7/site-packages/h11/_connection.py", line 443, in next_event
    exc._reraise_as_remote_protocol_error()
  File "/home/wooseok/anaconda3/envs/LGAPI/lib/python3.7/site-packages/h11/_util.py", line 76, in _reraise_as_remote_protocol_error
    raise self
  File "/home/wooseok/anaconda3/envs/LGAPI/lib/python3.7/site-packages/h11/_connection.py", line 425, in next_event
    event = self._extract_next_receive_event()
  File "/home/wooseok/anaconda3/envs/LGAPI/lib/python3.7/site-packages/h11/_connection.py", line 367, in _extract_next_receive_event
    event = self._reader(self._receive_buffer)
  File "/home/wooseok/anaconda3/envs/LGAPI/lib/python3.7/site-packages/h11/_readers.py", line 68, in maybe_read_from_IDLE_client
    raise LocalProtocolError("illegal request line")
h11._util.RemoteProtocolError: illegal request line
INFO:     89.248.164.165:41348 - "GET http%3A//www.baidu.com/cache/global/img/gs.gif HTTP/1.1" 404 Not Found
WARNING:  Invalid HTTP request received.
Traceback (most recent call last):
  File "/home/wooseok/anaconda3/envs/LGAPI/lib/python3.7/site-packages/uvicorn/protocols/http/h11_impl.py", line 172, in handle_events
    event = self.conn.next_event()
  File "/home/wooseok/anaconda3/envs/LGAPI/lib/python3.7/site-packages/h11/_connection.py", line 443, in next_event
    exc._reraise_as_remote_protocol_error()
  File "/home/wooseok/anaconda3/envs/LGAPI/lib/python3.7/site-packages/h11/_util.py", line 76, in _reraise_as_remote_protocol_error
    raise self
  File "/home/wooseok/anaconda3/envs/LGAPI/lib/python3.7/site-packages/h11/_connection.py", line 425, in next_event
    event = self._extract_next_receive_event()
  File "/home/wooseok/anaconda3/envs/LGAPI/lib/python3.7/site-packages/h11/_connection.py", line 367, in _extract_next_receive_event
    event = self._reader(self._receive_buffer)
  File "/home/wooseok/anaconda3/envs/LGAPI/lib/python3.7/site-packages/h11/_readers.py", line 68, in maybe_read_from_IDLE_client
    raise LocalProtocolError("illegal request line")
h11._util.RemoteProtocolError: illegal request line
INFO:     170.210.46.15:55468 - "POST /_ignition/execute-solution HTTP/1.1" 404 Not Found
INFO:     211.51.62.226:55024 - "POST /_ignition/execute-solution HTTP/1.1" 404 Not Found
INFO:     83.128.104.239:56025 - "GET / HTTP/1.0" 200 OK
INFO:     211.40.129.246:41244 - "POST /_ignition/execute-solution HTTP/1.1" 404 Not Found
WARNING:  Invalid HTTP request received.
Traceback (most recent call last):
  File "/home/wooseok/anaconda3/envs/LGAPI/lib/python3.7/site-packages/uvicorn/protocols/http/h11_impl.py", line 172, in handle_events
    event = self.conn.next_event()
  File "/home/wooseok/anaconda3/envs/LGAPI/lib/python3.7/site-packages/h11/_connection.py", line 443, in next_event
    exc._reraise_as_remote_protocol_error()
  File "/home/wooseok/anaconda3/envs/LGAPI/lib/python3.7/site-packages/h11/_util.py", line 76, in _reraise_as_remote_protocol_error
    raise self
  File "/home/wooseok/anaconda3/envs/LGAPI/lib/python3.7/site-packages/h11/_connection.py", line 425, in next_event
    event = self._extract_next_receive_event()
  File "/home/wooseok/anaconda3/envs/LGAPI/lib/python3.7/site-packages/h11/_connection.py", line 367, in _extract_next_receive_event
    event = self._reader(self._receive_buffer)
  File "/home/wooseok/anaconda3/envs/LGAPI/lib/python3.7/site-packages/h11/_readers.py", line 68, in maybe_read_from_IDLE_client
    raise LocalProtocolError("illegal request line")
h11._util.RemoteProtocolError: illegal request line
INFO:     183.136.225.14:48954 - "GET / HTTP/1.1" 200 OK
INFO:     183.136.225.14:42120 - "GET / HTTP/1.1" 200 OK
INFO:     183.136.225.14:44657 - "GET /favicon.ico HTTP/1.1" 404 Not Found
INFO:     74.82.47.3:56624 - "GET / HTTP/1.1" 200 OK
INFO:     128.14.209.162:55902 - "GET / HTTP/1.1" 200 OK
INFO:     34.96.130.20:55243 - "GET / HTTP/1.1" 200 OK
INFO:     88.5.238.31:34394 - "GET / HTTP/1.1" 200 OK
INFO:     74.120.14.56:48788 - "GET / HTTP/1.1" 200 OK
INFO:     74.120.14.56:51454 - "GET / HTTP/1.1" 200 OK
INFO:     139.59.129.12:53112 - "GET / HTTP/1.1" 200 OK
INFO:     185.216.140.186:43360 - "GET http%3A//www.baidu.com/cache/global/img/gs.gif HTTP/1.1" 404 Not Found
WARNING:  Invalid HTTP request received.
Traceback (most recent call last):
  File "/home/wooseok/anaconda3/envs/LGAPI/lib/python3.7/site-packages/uvicorn/protocols/http/h11_impl.py", line 172, in handle_events
    event = self.conn.next_event()
  File "/home/wooseok/anaconda3/envs/LGAPI/lib/python3.7/site-packages/h11/_connection.py", line 443, in next_event
    exc._reraise_as_remote_protocol_error()
  File "/home/wooseok/anaconda3/envs/LGAPI/lib/python3.7/site-packages/h11/_util.py", line 76, in _reraise_as_remote_protocol_error
    raise self
  File "/home/wooseok/anaconda3/envs/LGAPI/lib/python3.7/site-packages/h11/_connection.py", line 425, in next_event
    event = self._extract_next_receive_event()
  File "/home/wooseok/anaconda3/envs/LGAPI/lib/python3.7/site-packages/h11/_connection.py", line 367, in _extract_next_receive_event
    event = self._reader(self._receive_buffer)
  File "/home/wooseok/anaconda3/envs/LGAPI/lib/python3.7/site-packages/h11/_readers.py", line 68, in maybe_read_from_IDLE_client
    raise LocalProtocolError("illegal request line")
h11._util.RemoteProtocolError: illegal request line
INFO:     46.101.50.168:46336 - "POST / HTTP/1.1" 405 Method Not Allowed
WARNING:  Invalid HTTP request received.
Traceback (most recent call last):
  File "/home/wooseok/anaconda3/envs/LGAPI/lib/python3.7/site-packages/uvicorn/protocols/http/h11_impl.py", line 172, in handle_events
    event = self.conn.next_event()
  File "/home/wooseok/anaconda3/envs/LGAPI/lib/python3.7/site-packages/h11/_connection.py", line 443, in next_event
    exc._reraise_as_remote_protocol_error()
  File "/home/wooseok/anaconda3/envs/LGAPI/lib/python3.7/site-packages/h11/_util.py", line 76, in _reraise_as_remote_protocol_error
    raise self
  File "/home/wooseok/anaconda3/envs/LGAPI/lib/python3.7/site-packages/h11/_connection.py", line 425, in next_event
    event = self._extract_next_receive_event()
  File "/home/wooseok/anaconda3/envs/LGAPI/lib/python3.7/site-packages/h11/_connection.py", line 367, in _extract_next_receive_event
    event = self._reader(self._receive_buffer)
  File "/home/wooseok/anaconda3/envs/LGAPI/lib/python3.7/site-packages/h11/_readers.py", line 68, in maybe_read_from_IDLE_client
    raise LocalProtocolError("illegal request line")
h11._util.RemoteProtocolError: illegal request line
WARNING:  Invalid HTTP request received.
Traceback (most recent call last):
  File "/home/wooseok/anaconda3/envs/LGAPI/lib/python3.7/site-packages/uvicorn/protocols/http/h11_impl.py", line 172, in handle_events
    event = self.conn.next_event()
  File "/home/wooseok/anaconda3/envs/LGAPI/lib/python3.7/site-packages/h11/_connection.py", line 443, in next_event
    exc._reraise_as_remote_protocol_error()
  File "/home/wooseok/anaconda3/envs/LGAPI/lib/python3.7/site-packages/h11/_util.py", line 76, in _reraise_as_remote_protocol_error
    raise self
  File "/home/wooseok/anaconda3/envs/LGAPI/lib/python3.7/site-packages/h11/_connection.py", line 425, in next_event
    event = self._extract_next_receive_event()
  File "/home/wooseok/anaconda3/envs/LGAPI/lib/python3.7/site-packages/h11/_connection.py", line 367, in _extract_next_receive_event
    event = self._reader(self._receive_buffer)
  File "/home/wooseok/anaconda3/envs/LGAPI/lib/python3.7/site-packages/h11/_readers.py", line 68, in maybe_read_from_IDLE_client
    raise LocalProtocolError("illegal request line")
h11._util.RemoteProtocolError: illegal request line
WARNING:  Invalid HTTP request received.
Traceback (most recent call last):
  File "/home/wooseok/anaconda3/envs/LGAPI/lib/python3.7/site-packages/uvicorn/protocols/http/h11_impl.py", line 172, in handle_events
    event = self.conn.next_event()
  File "/home/wooseok/anaconda3/envs/LGAPI/lib/python3.7/site-packages/h11/_connection.py", line 443, in next_event
    exc._reraise_as_remote_protocol_error()
  File "/home/wooseok/anaconda3/envs/LGAPI/lib/python3.7/site-packages/h11/_util.py", line 76, in _reraise_as_remote_protocol_error
    raise self
  File "/home/wooseok/anaconda3/envs/LGAPI/lib/python3.7/site-packages/h11/_connection.py", line 425, in next_event
    event = self._extract_next_receive_event()
  File "/home/wooseok/anaconda3/envs/LGAPI/lib/python3.7/site-packages/h11/_connection.py", line 367, in _extract_next_receive_event
    event = self._reader(self._receive_buffer)
  File "/home/wooseok/anaconda3/envs/LGAPI/lib/python3.7/site-packages/h11/_readers.py", line 68, in maybe_read_from_IDLE_client
    raise LocalProtocolError("illegal request line")
h11._util.RemoteProtocolError: illegal request line
WARNING:  Invalid HTTP request received.
Traceback (most recent call last):
  File "/home/wooseok/anaconda3/envs/LGAPI/lib/python3.7/site-packages/uvicorn/protocols/http/h11_impl.py", line 172, in handle_events
    event = self.conn.next_event()
  File "/home/wooseok/anaconda3/envs/LGAPI/lib/python3.7/site-packages/h11/_connection.py", line 443, in next_event
    exc._reraise_as_remote_protocol_error()
  File "/home/wooseok/anaconda3/envs/LGAPI/lib/python3.7/site-packages/h11/_util.py", line 76, in _reraise_as_remote_protocol_error
    raise self
  File "/home/wooseok/anaconda3/envs/LGAPI/lib/python3.7/site-packages/h11/_connection.py", line 425, in next_event
    event = self._extract_next_receive_event()
  File "/home/wooseok/anaconda3/envs/LGAPI/lib/python3.7/site-packages/h11/_connection.py", line 367, in _extract_next_receive_event
    event = self._reader(self._receive_buffer)
  File "/home/wooseok/anaconda3/envs/LGAPI/lib/python3.7/site-packages/h11/_readers.py", line 68, in maybe_read_from_IDLE_client
    raise LocalProtocolError("illegal request line")
h11._util.RemoteProtocolError: illegal request line
INFO:     139.177.195.74:41974 - "POST / HTTP/1.1" 405 Method Not Allowed
WARNING:  Invalid HTTP request received.
Traceback (most recent call last):
  File "/home/wooseok/anaconda3/envs/LGAPI/lib/python3.7/site-packages/uvicorn/protocols/http/h11_impl.py", line 172, in handle_events
    event = self.conn.next_event()
  File "/home/wooseok/anaconda3/envs/LGAPI/lib/python3.7/site-packages/h11/_connection.py", line 443, in next_event
    exc._reraise_as_remote_protocol_error()
  File "/home/wooseok/anaconda3/envs/LGAPI/lib/python3.7/site-packages/h11/_util.py", line 76, in _reraise_as_remote_protocol_error
    raise self
  File "/home/wooseok/anaconda3/envs/LGAPI/lib/python3.7/site-packages/h11/_connection.py", line 425, in next_event
    event = self._extract_next_receive_event()
  File "/home/wooseok/anaconda3/envs/LGAPI/lib/python3.7/site-packages/h11/_connection.py", line 367, in _extract_next_receive_event
    event = self._reader(self._receive_buffer)
  File "/home/wooseok/anaconda3/envs/LGAPI/lib/python3.7/site-packages/h11/_readers.py", line 68, in maybe_read_from_IDLE_client
    raise LocalProtocolError("illegal request line")
h11._util.RemoteProtocolError: illegal request line
WARNING:  Invalid HTTP request received.
Traceback (most recent call last):
  File "/home/wooseok/anaconda3/envs/LGAPI/lib/python3.7/site-packages/uvicorn/protocols/http/h11_impl.py", line 172, in handle_events
    event = self.conn.next_event()
  File "/home/wooseok/anaconda3/envs/LGAPI/lib/python3.7/site-packages/h11/_connection.py", line 443, in next_event
    exc._reraise_as_remote_protocol_error()
  File "/home/wooseok/anaconda3/envs/LGAPI/lib/python3.7/site-packages/h11/_util.py", line 76, in _reraise_as_remote_protocol_error
    raise self
  File "/home/wooseok/anaconda3/envs/LGAPI/lib/python3.7/site-packages/h11/_connection.py", line 425, in next_event
    event = self._extract_next_receive_event()
  File "/home/wooseok/anaconda3/envs/LGAPI/lib/python3.7/site-packages/h11/_connection.py", line 367, in _extract_next_receive_event
    event = self._reader(self._receive_buffer)
  File "/home/wooseok/anaconda3/envs/LGAPI/lib/python3.7/site-packages/h11/_readers.py", line 68, in maybe_read_from_IDLE_client
    raise LocalProtocolError("illegal request line")
h11._util.RemoteProtocolError: illegal request line
WARNING:  Invalid HTTP request received.
Traceback (most recent call last):
  File "/home/wooseok/anaconda3/envs/LGAPI/lib/python3.7/site-packages/uvicorn/protocols/http/h11_impl.py", line 172, in handle_events
    event = self.conn.next_event()
  File "/home/wooseok/anaconda3/envs/LGAPI/lib/python3.7/site-packages/h11/_connection.py", line 443, in next_event
    exc._reraise_as_remote_protocol_error()
  File "/home/wooseok/anaconda3/envs/LGAPI/lib/python3.7/site-packages/h11/_util.py", line 76, in _reraise_as_remote_protocol_error
    raise self
  File "/home/wooseok/anaconda3/envs/LGAPI/lib/python3.7/site-packages/h11/_connection.py", line 425, in next_event
    event = self._extract_next_receive_event()
  File "/home/wooseok/anaconda3/envs/LGAPI/lib/python3.7/site-packages/h11/_connection.py", line 367, in _extract_next_receive_event
    event = self._reader(self._receive_buffer)
  File "/home/wooseok/anaconda3/envs/LGAPI/lib/python3.7/site-packages/h11/_readers.py", line 68, in maybe_read_from_IDLE_client
    raise LocalProtocolError("illegal request line")
h11._util.RemoteProtocolError: illegal request line
WARNING:  Invalid HTTP request received.
Traceback (most recent call last):
  File "/home/wooseok/anaconda3/envs/LGAPI/lib/python3.7/site-packages/uvicorn/protocols/http/h11_impl.py", line 172, in handle_events
    event = self.conn.next_event()
  File "/home/wooseok/anaconda3/envs/LGAPI/lib/python3.7/site-packages/h11/_connection.py", line 443, in next_event
    exc._reraise_as_remote_protocol_error()
  File "/home/wooseok/anaconda3/envs/LGAPI/lib/python3.7/site-packages/h11/_util.py", line 76, in _reraise_as_remote_protocol_error
    raise self
  File "/home/wooseok/anaconda3/envs/LGAPI/lib/python3.7/site-packages/h11/_connection.py", line 425, in next_event
    event = self._extract_next_receive_event()
  File "/home/wooseok/anaconda3/envs/LGAPI/lib/python3.7/site-packages/h11/_connection.py", line 367, in _extract_next_receive_event
    event = self._reader(self._receive_buffer)
  File "/home/wooseok/anaconda3/envs/LGAPI/lib/python3.7/site-packages/h11/_readers.py", line 68, in maybe_read_from_IDLE_client
    raise LocalProtocolError("illegal request line")
h11._util.RemoteProtocolError: illegal request line
INFO:     74.82.47.2:39570 - "GET / HTTP/1.1" 200 OK
INFO:     192.168.0.1:61485 - "GET / HTTP/1.1" 200 OK
INFO:     192.168.0.1:61485 - "GET /favicon.ico HTTP/1.1" 404 Not Found
INFO:     192.168.0.1:61485 - "GET /docs HTTP/1.1" 200 OK
INFO:     192.168.0.1:61485 - "GET /openapi.json HTTP/1.1" 200 OK
INFO:     58.227.149.49:59462 - "GET /docs HTTP/1.1" 200 OK
INFO:     58.227.149.49:59462 - "GET /openapi.json HTTP/1.1" 200 OK
INFO:     14.45.204.35:63550 - "GET /docs HTTP/1.1" 200 OK
INFO:     14.45.204.35:63550 - "GET /openapi.json HTTP/1.1" 200 OK
WARNING:  Invalid HTTP request received.
Traceback (most recent call last):
  File "/home/wooseok/anaconda3/envs/LGAPI/lib/python3.7/site-packages/uvicorn/protocols/http/h11_impl.py", line 172, in handle_events
    event = self.conn.next_event()
  File "/home/wooseok/anaconda3/envs/LGAPI/lib/python3.7/site-packages/h11/_connection.py", line 443, in next_event
    exc._reraise_as_remote_protocol_error()
  File "/home/wooseok/anaconda3/envs/LGAPI/lib/python3.7/site-packages/h11/_util.py", line 76, in _reraise_as_remote_protocol_error
    raise self
  File "/home/wooseok/anaconda3/envs/LGAPI/lib/python3.7/site-packages/h11/_connection.py", line 425, in next_event
    event = self._extract_next_receive_event()
  File "/home/wooseok/anaconda3/envs/LGAPI/lib/python3.7/site-packages/h11/_connection.py", line 367, in _extract_next_receive_event
    event = self._reader(self._receive_buffer)
  File "/home/wooseok/anaconda3/envs/LGAPI/lib/python3.7/site-packages/h11/_readers.py", line 68, in maybe_read_from_IDLE_client
    raise LocalProtocolError("illegal request line")
h11._util.RemoteProtocolError: illegal request line
INFO:     104.140.188.2:55443 - "GET / HTTP/1.1" 200 OK
INFO:     180.149.125.175:11981 - "GET /c/ HTTP/1.1" 404 Not Found
WARNING:  Invalid HTTP request received.
Traceback (most recent call last):
  File "/home/wooseok/anaconda3/envs/LGAPI/lib/python3.7/site-packages/uvicorn/protocols/http/h11_impl.py", line 172, in handle_events
    event = self.conn.next_event()
  File "/home/wooseok/anaconda3/envs/LGAPI/lib/python3.7/site-packages/h11/_connection.py", line 443, in next_event
    exc._reraise_as_remote_protocol_error()
  File "/home/wooseok/anaconda3/envs/LGAPI/lib/python3.7/site-packages/h11/_util.py", line 76, in _reraise_as_remote_protocol_error
    raise self
  File "/home/wooseok/anaconda3/envs/LGAPI/lib/python3.7/site-packages/h11/_connection.py", line 425, in next_event
    event = self._extract_next_receive_event()
  File "/home/wooseok/anaconda3/envs/LGAPI/lib/python3.7/site-packages/h11/_connection.py", line 367, in _extract_next_receive_event
    event = self._reader(self._receive_buffer)
  File "/home/wooseok/anaconda3/envs/LGAPI/lib/python3.7/site-packages/h11/_readers.py", line 68, in maybe_read_from_IDLE_client
    raise LocalProtocolError("illegal request line")
h11._util.RemoteProtocolError: illegal request line
WARNING:  Invalid HTTP request received.
Traceback (most recent call last):
  File "/home/wooseok/anaconda3/envs/LGAPI/lib/python3.7/site-packages/uvicorn/protocols/http/h11_impl.py", line 172, in handle_events
    event = self.conn.next_event()
  File "/home/wooseok/anaconda3/envs/LGAPI/lib/python3.7/site-packages/h11/_connection.py", line 443, in next_event
    exc._reraise_as_remote_protocol_error()
  File "/home/wooseok/anaconda3/envs/LGAPI/lib/python3.7/site-packages/h11/_util.py", line 76, in _reraise_as_remote_protocol_error
    raise self
  File "/home/wooseok/anaconda3/envs/LGAPI/lib/python3.7/site-packages/h11/_connection.py", line 425, in next_event
    event = self._extract_next_receive_event()
  File "/home/wooseok/anaconda3/envs/LGAPI/lib/python3.7/site-packages/h11/_connection.py", line 367, in _extract_next_receive_event
    event = self._reader(self._receive_buffer)
  File "/home/wooseok/anaconda3/envs/LGAPI/lib/python3.7/site-packages/h11/_readers.py", line 68, in maybe_read_from_IDLE_client
    raise LocalProtocolError("illegal request line")
h11._util.RemoteProtocolError: illegal request line
WARNING:  Invalid HTTP request received.
Traceback (most recent call last):
  File "/home/wooseok/anaconda3/envs/LGAPI/lib/python3.7/site-packages/uvicorn/protocols/http/h11_impl.py", line 172, in handle_events
    event = self.conn.next_event()
  File "/home/wooseok/anaconda3/envs/LGAPI/lib/python3.7/site-packages/h11/_connection.py", line 443, in next_event
    exc._reraise_as_remote_protocol_error()
  File "/home/wooseok/anaconda3/envs/LGAPI/lib/python3.7/site-packages/h11/_util.py", line 76, in _reraise_as_remote_protocol_error
    raise self
  File "/home/wooseok/anaconda3/envs/LGAPI/lib/python3.7/site-packages/h11/_connection.py", line 425, in next_event
    event = self._extract_next_receive_event()
  File "/home/wooseok/anaconda3/envs/LGAPI/lib/python3.7/site-packages/h11/_connection.py", line 367, in _extract_next_receive_event
    event = self._reader(self._receive_buffer)
  File "/home/wooseok/anaconda3/envs/LGAPI/lib/python3.7/site-packages/h11/_readers.py", line 68, in maybe_read_from_IDLE_client
    raise LocalProtocolError("illegal request line")
h11._util.RemoteProtocolError: illegal request line
WARNING:  Invalid HTTP request received.
Traceback (most recent call last):
  File "/home/wooseok/anaconda3/envs/LGAPI/lib/python3.7/site-packages/uvicorn/protocols/http/h11_impl.py", line 172, in handle_events
    event = self.conn.next_event()
  File "/home/wooseok/anaconda3/envs/LGAPI/lib/python3.7/site-packages/h11/_connection.py", line 443, in next_event
    exc._reraise_as_remote_protocol_error()
  File "/home/wooseok/anaconda3/envs/LGAPI/lib/python3.7/site-packages/h11/_util.py", line 76, in _reraise_as_remote_protocol_error
    raise self
  File "/home/wooseok/anaconda3/envs/LGAPI/lib/python3.7/site-packages/h11/_connection.py", line 425, in next_event
    event = self._extract_next_receive_event()
  File "/home/wooseok/anaconda3/envs/LGAPI/lib/python3.7/site-packages/h11/_connection.py", line 367, in _extract_next_receive_event
    event = self._reader(self._receive_buffer)
  File "/home/wooseok/anaconda3/envs/LGAPI/lib/python3.7/site-packages/h11/_readers.py", line 68, in maybe_read_from_IDLE_client
    raise LocalProtocolError("illegal request line")
h11._util.RemoteProtocolError: illegal request line
WARNING:  Invalid HTTP request received.
Traceback (most recent call last):
  File "/home/wooseok/anaconda3/envs/LGAPI/lib/python3.7/site-packages/uvicorn/protocols/http/h11_impl.py", line 172, in handle_events
    event = self.conn.next_event()
  File "/home/wooseok/anaconda3/envs/LGAPI/lib/python3.7/site-packages/h11/_connection.py", line 443, in next_event
    exc._reraise_as_remote_protocol_error()
  File "/home/wooseok/anaconda3/envs/LGAPI/lib/python3.7/site-packages/h11/_util.py", line 76, in _reraise_as_remote_protocol_error
    raise self
  File "/home/wooseok/anaconda3/envs/LGAPI/lib/python3.7/site-packages/h11/_connection.py", line 425, in next_event
    event = self._extract_next_receive_event()
  File "/home/wooseok/anaconda3/envs/LGAPI/lib/python3.7/site-packages/h11/_connection.py", line 367, in _extract_next_receive_event
    event = self._reader(self._receive_buffer)
  File "/home/wooseok/anaconda3/envs/LGAPI/lib/python3.7/site-packages/h11/_readers.py", line 68, in maybe_read_from_IDLE_client
    raise LocalProtocolError("illegal request line")
h11._util.RemoteProtocolError: illegal request line
WARNING:  Invalid HTTP request received.
Traceback (most recent call last):
  File "/home/wooseok/anaconda3/envs/LGAPI/lib/python3.7/site-packages/uvicorn/protocols/http/h11_impl.py", line 172, in handle_events
    event = self.conn.next_event()
  File "/home/wooseok/anaconda3/envs/LGAPI/lib/python3.7/site-packages/h11/_connection.py", line 443, in next_event
    exc._reraise_as_remote_protocol_error()
  File "/home/wooseok/anaconda3/envs/LGAPI/lib/python3.7/site-packages/h11/_util.py", line 76, in _reraise_as_remote_protocol_error
    raise self
  File "/home/wooseok/anaconda3/envs/LGAPI/lib/python3.7/site-packages/h11/_connection.py", line 425, in next_event
    event = self._extract_next_receive_event()
  File "/home/wooseok/anaconda3/envs/LGAPI/lib/python3.7/site-packages/h11/_connection.py", line 367, in _extract_next_receive_event
    event = self._reader(self._receive_buffer)
  File "/home/wooseok/anaconda3/envs/LGAPI/lib/python3.7/site-packages/h11/_readers.py", line 68, in maybe_read_from_IDLE_client
    raise LocalProtocolError("illegal request line")
h11._util.RemoteProtocolError: illegal request line
WARNING:  Invalid HTTP request received.
Traceback (most recent call last):
  File "/home/wooseok/anaconda3/envs/LGAPI/lib/python3.7/site-packages/uvicorn/protocols/http/h11_impl.py", line 172, in handle_events
    event = self.conn.next_event()
  File "/home/wooseok/anaconda3/envs/LGAPI/lib/python3.7/site-packages/h11/_connection.py", line 443, in next_event
    exc._reraise_as_remote_protocol_error()
  File "/home/wooseok/anaconda3/envs/LGAPI/lib/python3.7/site-packages/h11/_util.py", line 76, in _reraise_as_remote_protocol_error
    raise self
  File "/home/wooseok/anaconda3/envs/LGAPI/lib/python3.7/site-packages/h11/_connection.py", line 425, in next_event
    event = self._extract_next_receive_event()
  File "/home/wooseok/anaconda3/envs/LGAPI/lib/python3.7/site-packages/h11/_connection.py", line 367, in _extract_next_receive_event
    event = self._reader(self._receive_buffer)
  File "/home/wooseok/anaconda3/envs/LGAPI/lib/python3.7/site-packages/h11/_readers.py", line 68, in maybe_read_from_IDLE_client
    raise LocalProtocolError("illegal request line")
h11._util.RemoteProtocolError: illegal request line
WARNING:  Invalid HTTP request received.
Traceback (most recent call last):
  File "/home/wooseok/anaconda3/envs/LGAPI/lib/python3.7/site-packages/uvicorn/protocols/http/h11_impl.py", line 172, in handle_events
    event = self.conn.next_event()
  File "/home/wooseok/anaconda3/envs/LGAPI/lib/python3.7/site-packages/h11/_connection.py", line 443, in next_event
    exc._reraise_as_remote_protocol_error()
  File "/home/wooseok/anaconda3/envs/LGAPI/lib/python3.7/site-packages/h11/_util.py", line 76, in _reraise_as_remote_protocol_error
    raise self
  File "/home/wooseok/anaconda3/envs/LGAPI/lib/python3.7/site-packages/h11/_connection.py", line 425, in next_event
    event = self._extract_next_receive_event()
  File "/home/wooseok/anaconda3/envs/LGAPI/lib/python3.7/site-packages/h11/_connection.py", line 367, in _extract_next_receive_event
    event = self._reader(self._receive_buffer)
  File "/home/wooseok/anaconda3/envs/LGAPI/lib/python3.7/site-packages/h11/_readers.py", line 68, in maybe_read_from_IDLE_client
    raise LocalProtocolError("illegal request line")
h11._util.RemoteProtocolError: illegal request line
INFO:     192.168.0.1:55975 - "GET / HTTP/1.1" 200 OK
INFO:     192.168.0.1:55975 - "GET /favicon.ico HTTP/1.1" 404 Not Found
WARNING:  Invalid HTTP request received.
Traceback (most recent call last):
  File "/home/wooseok/anaconda3/envs/LGAPI/lib/python3.7/site-packages/uvicorn/protocols/http/h11_impl.py", line 172, in handle_events
    event = self.conn.next_event()
  File "/home/wooseok/anaconda3/envs/LGAPI/lib/python3.7/site-packages/h11/_connection.py", line 443, in next_event
    exc._reraise_as_remote_protocol_error()
  File "/home/wooseok/anaconda3/envs/LGAPI/lib/python3.7/site-packages/h11/_util.py", line 76, in _reraise_as_remote_protocol_error
    raise self
  File "/home/wooseok/anaconda3/envs/LGAPI/lib/python3.7/site-packages/h11/_connection.py", line 425, in next_event
    event = self._extract_next_receive_event()
  File "/home/wooseok/anaconda3/envs/LGAPI/lib/python3.7/site-packages/h11/_connection.py", line 367, in _extract_next_receive_event
    event = self._reader(self._receive_buffer)
  File "/home/wooseok/anaconda3/envs/LGAPI/lib/python3.7/site-packages/h11/_readers.py", line 68, in maybe_read_from_IDLE_client
    raise LocalProtocolError("illegal request line")
h11._util.RemoteProtocolError: illegal request line
INFO:     58.227.53.209:58588 - "GET /docs HTTP/1.1" 200 OK
INFO:     58.227.53.209:58588 - "GET /openapi.json HTTP/1.1" 200 OK
INFO:     80.82.77.33:50050 - "GET / HTTP/1.1" 200 OK
INFO:     80.82.77.33:53860 - "GET /favicon.ico HTTP/1.1" 404 Not Found
WARNING:  Invalid HTTP request received.
Traceback (most recent call last):
  File "/home/wooseok/anaconda3/envs/LGAPI/lib/python3.7/site-packages/uvicorn/protocols/http/h11_impl.py", line 172, in handle_events
    event = self.conn.next_event()
  File "/home/wooseok/anaconda3/envs/LGAPI/lib/python3.7/site-packages/h11/_connection.py", line 443, in next_event
    exc._reraise_as_remote_protocol_error()
  File "/home/wooseok/anaconda3/envs/LGAPI/lib/python3.7/site-packages/h11/_util.py", line 76, in _reraise_as_remote_protocol_error
    raise self
  File "/home/wooseok/anaconda3/envs/LGAPI/lib/python3.7/site-packages/h11/_connection.py", line 425, in next_event
    event = self._extract_next_receive_event()
  File "/home/wooseok/anaconda3/envs/LGAPI/lib/python3.7/site-packages/h11/_connection.py", line 367, in _extract_next_receive_event
    event = self._reader(self._receive_buffer)
  File "/home/wooseok/anaconda3/envs/LGAPI/lib/python3.7/site-packages/h11/_readers.py", line 68, in maybe_read_from_IDLE_client
    raise LocalProtocolError("illegal request line")
h11._util.RemoteProtocolError: illegal request line
INFO:     34.76.80.167:60174 - "GET / HTTP/1.1" 200 OK
INFO:     192.168.0.1:1988 - "GET / HTTP/1.1" 200 OK
INFO:     192.168.0.1:1988 - "GET /favicon.ico HTTP/1.1" 404 Not Found
INFO:     192.168.0.1:1989 - "GET /docs HTTP/1.1" 200 OK
INFO:     192.168.0.1:1989 - "GET /openapi.json HTTP/1.1" 200 OK
INFO:     192.168.0.1:2337 - "POST /posts HTTP/1.1" 200 OK
INFO:     192.168.0.1:2360 - "GET /posts/1 HTTP/1.1" 200 OK
INFO:     192.168.0.1:4210 - "GET /docs HTTP/1.1" 200 OK
INFO:     192.168.0.1:4210 - "GET /openapi.json HTTP/1.1" 200 OK
INFO:     192.168.0.1:4211 - "POST /posts HTTP/1.1" 200 OK
INFO:     58.227.53.209:57395 - "GET /docs HTTP/1.1" 200 OK
INFO:     58.227.53.209:57395 - "GET /openapi.json HTTP/1.1" 200 OK
INFO:     180.149.125.175:45565 - "GET / HTTP/1.1" 200 OK
INFO:     167.248.133.53:37396 - "GET / HTTP/1.1" 200 OK
INFO:     167.248.133.53:51994 - "GET / HTTP/1.1" 200 OK
INFO:     89.248.164.165:58236 - "GET http%3A//www.baidu.com/cache/global/img/gs.gif HTTP/1.1" 404 Not Found
INFO:     183.136.225.14:55307 - "GET / HTTP/1.1" 200 OK
INFO:     183.136.225.14:18096 - "GET / HTTP/1.1" 200 OK
INFO:     183.136.225.14:20565 - "GET /favicon.ico HTTP/1.1" 404 Not Found
INFO:     65.49.20.66:60978 - "GET / HTTP/1.1" 200 OK
WARNING:  Invalid HTTP request received.
Traceback (most recent call last):
  File "/home/wooseok/anaconda3/envs/LGAPI/lib/python3.7/site-packages/uvicorn/protocols/http/h11_impl.py", line 172, in handle_events
    event = self.conn.next_event()
  File "/home/wooseok/anaconda3/envs/LGAPI/lib/python3.7/site-packages/h11/_connection.py", line 443, in next_event
    exc._reraise_as_remote_protocol_error()
  File "/home/wooseok/anaconda3/envs/LGAPI/lib/python3.7/site-packages/h11/_util.py", line 76, in _reraise_as_remote_protocol_error
    raise self
  File "/home/wooseok/anaconda3/envs/LGAPI/lib/python3.7/site-packages/h11/_connection.py", line 425, in next_event
    event = self._extract_next_receive_event()
  File "/home/wooseok/anaconda3/envs/LGAPI/lib/python3.7/site-packages/h11/_connection.py", line 367, in _extract_next_receive_event
    event = self._reader(self._receive_buffer)
  File "/home/wooseok/anaconda3/envs/LGAPI/lib/python3.7/site-packages/h11/_readers.py", line 68, in maybe_read_from_IDLE_client
    raise LocalProtocolError("illegal request line")
h11._util.RemoteProtocolError: illegal request line
INFO:     185.220.102.241:18104 - "GET / HTTP/1.1" 200 OK
WARNING:  Invalid HTTP request received.
Traceback (most recent call last):
  File "/home/wooseok/anaconda3/envs/LGAPI/lib/python3.7/site-packages/uvicorn/protocols/http/h11_impl.py", line 172, in handle_events
    event = self.conn.next_event()
  File "/home/wooseok/anaconda3/envs/LGAPI/lib/python3.7/site-packages/h11/_connection.py", line 443, in next_event
    exc._reraise_as_remote_protocol_error()
  File "/home/wooseok/anaconda3/envs/LGAPI/lib/python3.7/site-packages/h11/_util.py", line 76, in _reraise_as_remote_protocol_error
    raise self
  File "/home/wooseok/anaconda3/envs/LGAPI/lib/python3.7/site-packages/h11/_connection.py", line 425, in next_event
    event = self._extract_next_receive_event()
  File "/home/wooseok/anaconda3/envs/LGAPI/lib/python3.7/site-packages/h11/_connection.py", line 367, in _extract_next_receive_event
    event = self._reader(self._receive_buffer)
  File "/home/wooseok/anaconda3/envs/LGAPI/lib/python3.7/site-packages/h11/_readers.py", line 68, in maybe_read_from_IDLE_client
    raise LocalProtocolError("illegal request line")
h11._util.RemoteProtocolError: illegal request line
INFO:     178.32.197.84:38649 - "GET / HTTP/1.1" 200 OK
INFO:     62.210.10.77:46821 - "GET /favicon.ico HTTP/1.1" 404 Not Found
INFO:     74.120.14.37:43126 - "GET / HTTP/1.1" 200 OK
INFO:     74.120.14.37:47812 - "GET / HTTP/1.1" 200 OK
INFO:     184.105.247.254:58144 - "GET / HTTP/1.1" 200 OK
INFO:     162.142.125.39:46882 - "GET / HTTP/1.1" 200 OK
INFO:     162.142.125.39:34786 - "GET / HTTP/1.1" 200 OK
INFO:     58.227.149.49:59343 - "GET /docs HTTP/1.1" 200 OK
INFO:     58.227.149.49:59343 - "GET /openapi.json HTTP/1.1" 200 OK
WARNING:  Invalid HTTP request received.
Traceback (most recent call last):
  File "/home/wooseok/anaconda3/envs/LGAPI/lib/python3.7/site-packages/uvicorn/protocols/http/h11_impl.py", line 172, in handle_events
    event = self.conn.next_event()
  File "/home/wooseok/anaconda3/envs/LGAPI/lib/python3.7/site-packages/h11/_connection.py", line 443, in next_event
    exc._reraise_as_remote_protocol_error()
  File "/home/wooseok/anaconda3/envs/LGAPI/lib/python3.7/site-packages/h11/_util.py", line 76, in _reraise_as_remote_protocol_error
    raise self
  File "/home/wooseok/anaconda3/envs/LGAPI/lib/python3.7/site-packages/h11/_connection.py", line 425, in next_event
    event = self._extract_next_receive_event()
  File "/home/wooseok/anaconda3/envs/LGAPI/lib/python3.7/site-packages/h11/_connection.py", line 367, in _extract_next_receive_event
    event = self._reader(self._receive_buffer)
  File "/home/wooseok/anaconda3/envs/LGAPI/lib/python3.7/site-packages/h11/_readers.py", line 68, in maybe_read_from_IDLE_client
    raise LocalProtocolError("illegal request line")
h11._util.RemoteProtocolError: illegal request line
INFO:     58.227.149.49:62526 - "GET /openapi.json HTTP/1.1" 200 OK
INFO:     205.185.117.39:51346 - "GET / HTTP/1.1" 200 OK
INFO:     74.120.14.56:46312 - "GET / HTTP/1.1" 200 OK
INFO:     74.120.14.56:50710 - "GET / HTTP/1.1" 200 OK
INFO:     112.74.169.221:55076 - "POST /_ignition/execute-solution HTTP/1.1" 404 Not Found
WARNING:  Invalid HTTP request received.
Traceback (most recent call last):
  File "/home/wooseok/anaconda3/envs/LGAPI/lib/python3.7/site-packages/uvicorn/protocols/http/h11_impl.py", line 172, in handle_events
    event = self.conn.next_event()
  File "/home/wooseok/anaconda3/envs/LGAPI/lib/python3.7/site-packages/h11/_connection.py", line 443, in next_event
    exc._reraise_as_remote_protocol_error()
  File "/home/wooseok/anaconda3/envs/LGAPI/lib/python3.7/site-packages/h11/_util.py", line 76, in _reraise_as_remote_protocol_error
    raise self
  File "/home/wooseok/anaconda3/envs/LGAPI/lib/python3.7/site-packages/h11/_connection.py", line 425, in next_event
    event = self._extract_next_receive_event()
  File "/home/wooseok/anaconda3/envs/LGAPI/lib/python3.7/site-packages/h11/_connection.py", line 367, in _extract_next_receive_event
    event = self._reader(self._receive_buffer)
  File "/home/wooseok/anaconda3/envs/LGAPI/lib/python3.7/site-packages/h11/_readers.py", line 68, in maybe_read_from_IDLE_client
    raise LocalProtocolError("illegal request line")
h11._util.RemoteProtocolError: illegal request line
INFO:     184.105.139.67:33550 - "GET / HTTP/1.1" 200 OK
INFO:     104.206.128.2:36107 - "GET / HTTP/1.1" 200 OK
INFO:     167.99.36.121:61953 - "GET / HTTP/1.0" 200 OK
INFO:     45.95.169.105:42698 - "HEAD / HTTP/1.0" 405 Method Not Allowed
WARNING:  Invalid HTTP request received.
Traceback (most recent call last):
  File "/home/wooseok/anaconda3/envs/LGAPI/lib/python3.7/site-packages/uvicorn/protocols/http/h11_impl.py", line 172, in handle_events
    event = self.conn.next_event()
  File "/home/wooseok/anaconda3/envs/LGAPI/lib/python3.7/site-packages/h11/_connection.py", line 443, in next_event
    exc._reraise_as_remote_protocol_error()
  File "/home/wooseok/anaconda3/envs/LGAPI/lib/python3.7/site-packages/h11/_util.py", line 76, in _reraise_as_remote_protocol_error
    raise self
  File "/home/wooseok/anaconda3/envs/LGAPI/lib/python3.7/site-packages/h11/_connection.py", line 425, in next_event
    event = self._extract_next_receive_event()
  File "/home/wooseok/anaconda3/envs/LGAPI/lib/python3.7/site-packages/h11/_connection.py", line 367, in _extract_next_receive_event
    event = self._reader(self._receive_buffer)
  File "/home/wooseok/anaconda3/envs/LGAPI/lib/python3.7/site-packages/h11/_readers.py", line 68, in maybe_read_from_IDLE_client
    raise LocalProtocolError("illegal request line")
h11._util.RemoteProtocolError: illegal request line
INFO:     185.216.140.186:50346 - "GET http%3A//www.baidu.com/cache/global/img/gs.gif HTTP/1.1" 404 Not Found
WARNING:  Invalid HTTP request received.
Traceback (most recent call last):
  File "/home/wooseok/anaconda3/envs/LGAPI/lib/python3.7/site-packages/uvicorn/protocols/http/h11_impl.py", line 172, in handle_events
    event = self.conn.next_event()
  File "/home/wooseok/anaconda3/envs/LGAPI/lib/python3.7/site-packages/h11/_connection.py", line 443, in next_event
    exc._reraise_as_remote_protocol_error()
  File "/home/wooseok/anaconda3/envs/LGAPI/lib/python3.7/site-packages/h11/_util.py", line 76, in _reraise_as_remote_protocol_error
    raise self
  File "/home/wooseok/anaconda3/envs/LGAPI/lib/python3.7/site-packages/h11/_connection.py", line 425, in next_event
    event = self._extract_next_receive_event()
  File "/home/wooseok/anaconda3/envs/LGAPI/lib/python3.7/site-packages/h11/_connection.py", line 367, in _extract_next_receive_event
    event = self._reader(self._receive_buffer)
  File "/home/wooseok/anaconda3/envs/LGAPI/lib/python3.7/site-packages/h11/_readers.py", line 68, in maybe_read_from_IDLE_client
    raise LocalProtocolError("illegal request line")
h11._util.RemoteProtocolError: illegal request line
INFO:     206.189.0.27:49050 - "GET / HTTP/1.1" 200 OK
INFO:     42.193.8.97:34712 - "GET / HTTP/1.1" 200 OK
WARNING:  Invalid HTTP request received.
Traceback (most recent call last):
  File "/home/wooseok/anaconda3/envs/LGAPI/lib/python3.7/site-packages/uvicorn/protocols/http/h11_impl.py", line 172, in handle_events
    event = self.conn.next_event()
  File "/home/wooseok/anaconda3/envs/LGAPI/lib/python3.7/site-packages/h11/_connection.py", line 443, in next_event
    exc._reraise_as_remote_protocol_error()
  File "/home/wooseok/anaconda3/envs/LGAPI/lib/python3.7/site-packages/h11/_util.py", line 76, in _reraise_as_remote_protocol_error
    raise self
  File "/home/wooseok/anaconda3/envs/LGAPI/lib/python3.7/site-packages/h11/_connection.py", line 425, in next_event
    event = self._extract_next_receive_event()
  File "/home/wooseok/anaconda3/envs/LGAPI/lib/python3.7/site-packages/h11/_connection.py", line 367, in _extract_next_receive_event
    event = self._reader(self._receive_buffer)
  File "/home/wooseok/anaconda3/envs/LGAPI/lib/python3.7/site-packages/h11/_readers.py", line 68, in maybe_read_from_IDLE_client
    raise LocalProtocolError("illegal request line")
h11._util.RemoteProtocolError: illegal request line
INFO:     39.100.157.15:36506 - "POST /_ignition/execute-solution HTTP/1.1" 404 Not Found
WARNING:  Invalid HTTP request received.
Traceback (most recent call last):
  File "/home/wooseok/anaconda3/envs/LGAPI/lib/python3.7/site-packages/uvicorn/protocols/http/h11_impl.py", line 172, in handle_events
    event = self.conn.next_event()
  File "/home/wooseok/anaconda3/envs/LGAPI/lib/python3.7/site-packages/h11/_connection.py", line 443, in next_event
    exc._reraise_as_remote_protocol_error()
  File "/home/wooseok/anaconda3/envs/LGAPI/lib/python3.7/site-packages/h11/_util.py", line 76, in _reraise_as_remote_protocol_error
    raise self
  File "/home/wooseok/anaconda3/envs/LGAPI/lib/python3.7/site-packages/h11/_connection.py", line 425, in next_event
    event = self._extract_next_receive_event()
  File "/home/wooseok/anaconda3/envs/LGAPI/lib/python3.7/site-packages/h11/_connection.py", line 367, in _extract_next_receive_event
    event = self._reader(self._receive_buffer)
  File "/home/wooseok/anaconda3/envs/LGAPI/lib/python3.7/site-packages/h11/_readers.py", line 68, in maybe_read_from_IDLE_client
    raise LocalProtocolError("illegal request line")
h11._util.RemoteProtocolError: illegal request line
INFO:     58.227.149.49:53226 - "GET /openapi.json HTTP/1.1" 200 OK
